Workbook

Sheet Management Summary
A1: MANAGEMENT SUMMARY | Insurance Portfolio Risk & Profitability Report
A2: Non-Life Insurance Portfolio | Actuarial Risk & Profitability Analysis | Base Case Scenario | March 2026 | Strictly Confidential
B4: P&L — Net Underwriting Profit | E4: Efficiency — Combined Ratio
B5: =Calculations!B11 -> 2000000 | E5: =Calculations!B18 -> 0.98
B7: Tail Risk — 99.5th Pctile VaR (₹) | E7: Capital — Solvency Ratio
B8: =Simulation!G9 -> 66960000 | E8: ='Capital & Solvency'!C20 -> 2.394636
B10: Underwriting — Loss Ratio | E10: Reinsurance — RI Risk Reduction
B11: =Calculations!B15 -> 0.6 | E11: =Calculations!C25 -> 0
B13: Ruin Risk — Prob. Loss > Premium | E13: Solvency II — Total Capital Req.
B14: =Simulation!G10 -> 0 | E14: ='Capital & Solvency'!C16 -> 8352000
A17: AUTOMATED RISK STATUS ASSESSMENT
B18: Area | E18: Area
B19: Profitability | C19: =IF(Calculations!B11>0,"✓ PROFITABLE","✗ LOSS-MAKING") -> ✓ PROFITABLE | E19: Combined Ratio | F19: =IF(Calculations!B18<0.95,"✓ HEALTHY (<95%)",IF(Calculations!B18<1,"⚠ WATCH (95-100%)","✗ DANGER (>100%)")) -> ⚠ WATCH (95-100%)
B20: Solvency | C20: =IF('Capital & Solvency'!C20>=1,"✓ SOLVENT","✗ CAPITAL SHORTFALL") -> ✓ SOLVENT | E20: Pricing | F20: =IF('Pricing Adequacy'!C20>=1,"✓ ADEQUATELY PRICED","✗ REVIEW PRICING") -> ✗ REVIEW PRICING
A22: EXECUTIVE RECOMMENDATION
A23: MODEL PURPOSE This model evaluates the profitability, risk exposure, and capital adequacy of a non-life insurance portfolio using deterministic underwriting analysis and stochastic Monte Carlo simulation (Poisson frequency model, 5,000 trials). It is designed to answer five core business questions: Is the portfolio profitable? How sensitive is profit to key assumptions? What is the tail loss at 99.5th percentile (Solvency II)? Is the company solvent? Is the premium adequate to cover all costs including a capital charge? KEY FINDINGS (Base Case) The portfolio is technically profitable on a gross underwriting basis, with a positive net underwriting margin of ₹2,000,000 (2.0% of premium). However, the full pricing adequacy test — which includes a capital cost charge of ₹5,000,000 — shows the portfolio is under-priced. The current gross premium of ₹100,000,000 falls short of the required premium of ₹104,800,000 (adequacy ratio: 0.954x). A rate increase of approximately 4.8% is required to achieve full pricing adequacy. The combined ratio of 98% is within a profitable range but exceeds the 95% target benchmark, placing it on watch. The Solvency Ratio substantially exceeds the 1.0x minimum, confirming strong capital adequacy — refer to the Capital & Solvency sheet for the current simulation-derived figure. PRIMARY RISK DRIVER Sensitivity analysis identifies claim frequency as the dominant risk driver. A +30% adverse frequency shock (e.g. a high-claims year or deteriorating risk selection) would materially reduce the profit margin and push the portfolio into loss. Claim severity (inflation) is the secondary driver. These two factors together account for the majority of P&L volatility. Additionally, the current XL reinsurance treaty (₹500,000 retention per claim) provides no protection under base case assumptions, as average claim severity (₹120,000) is well below the attachment point — leaving the portfolio fully exposed to any large individual losses. RECOMMENDED ACTIONS 1. Implement a rate increase of ~5% at next renewal to close the pricing adequacy deficit. 2. Monitor actual claim frequency monthly vs. budget — early warning indicator for adverse years. 3. Review the retention limit (currently ₹500,000) against average and 99th percentile claim severity; consider lowering it to a level where the XL treaty provides meaningful risk transfer. 4. Confirm available capital continues to exceed Total Capital Requirement as the portfolio grows — current Total Capital Requirement is shown in the Capital & Solvency sheet. 5. Extend model to multi-year projection with claims inflation loading as next development step.

Sheet Inputs
A1: INSURANCE RISK MODEL | Assumptions & Inputs
A2: All monetary values in INR | Blue cells are user inputs
A4: SCENARIO SELECTION
A5: Active Scenario | B5: Base | D5: Base | E5: Optimistic | F5: Stress
A7: PORTFOLIO PARAMETERS
A8: Assumption | B8: Value | C8: Notes / Source | D8: Base | E8: Optimistic | F8: Stress
A9: Annual Gross Premium (₹) | B9: 100000000 | C9: Total premium written before reinsurance | D9: 100000000 | E9: 120000000 | F9: 80000000
A10: Number of Policies | B10: 50000 | C10: In-force policy count | D10: 50000 | E10: 60000 | F10: 40000
A11: Claim Frequency (per policy) | B11: 0.01 | C11: Historical 5yr average claim rate | D11: 0.01 | E11: 0.005 | F11: 0.02
A12: Average Claim Severity (₹) | B12: 120000 | C12: Mean incurred loss per claim | D12: 120000 | E12: 100000 | F12: 150000
A13: Expense Ratio | B13: 0.3 | C13: Operating expenses / Gross premium | D13: 0.3 | E13: 0.28 | F13: 0.33
A14: XL Retention Limit per Claim (₹) | B14: 500000 | C14: Per-occurrence XL attachment point | D14: 500000 | E14: 500000 | F14: 500000
A15: XL Limit per Claim (₹) | B15: 4500000 | C15: Maximum XL recovery per claim | D15: 4500000 | E15: 4500000 | F15: 4500000
A16: Reinsurance Cost (% of Premium) | B16: 0.08 | C16: RI cession cost / Gross premium | D16: 0.08 | E16: 0.07 | F16: 0.1

Sheet Calculations
A1: CALCULATIONS | Underwriting P&L & Reinsurance Analysis
A2: Green text = cross-sheet reference | Black text = formula
A4: A. UNDERWRITING PROFIT & LOSS
A5: Line Item | B5: Amount (₹) | C5: % of Premium
A6: Gross Written Premium | B6: =Inputs!B9 -> 100000000 | C6: =B6/B6 -> 1
A7: Expected Claim Count | B7: =Inputs!B10*Inputs!B11 -> 500
A8: Expected Gross Claims (₹) | B8: =B7*Inputs!B12 -> 60000000 | C8: =B8/B6 -> 0.6
A9: Operating Expenses (₹) | B9: =Inputs!B9*Inputs!B13 -> 30000000 | C9: =B9/B6 -> 0.3
A10: Reinsurance Cost (₹) | B10: =Inputs!B9*Inputs!B16 -> 8000000 | C10: =B10/B6 -> 0.08
A11: Net Underwriting Profit (₹) | B11: =B6-(B8+B9+B10) -> 2000000 | C11: =B11/B6 -> 0.02
A13: B. KEY UNDERWRITING RATIOS
A14: Ratio | B14: Value | C14: Benchmark
A15: Loss Ratio | B15: =B8/B6 -> 0.6 | C15: < 60%
A16: Expense Ratio | B16: =B9/B6 -> 0.3 | C16: < 35%
A17: Reinsurance Cost Ratio | B17: =B10/B6 -> 0.08 | C17: < 10%
A18: Combined Ratio | B18: =(B8+B9+B10)/B6 -> 0.98 | C18: < 100%
A20: C. REINSURANCE RECOVERY ANALYSIS
A21: Item | B21: Per Claim (₹) | C21: Total Portfolio (₹)
A22: Gross Claim Severity | B22: =Inputs!B12 -> 120000 | C22: =B7*Inputs!B12 -> 60000000
A23: Insurer Net Retention per Claim | B23: =MIN(Inputs!B12,Inputs!B14) -> 120000 | C23: =B7*B23 -> 60000000
A24: Reinsurer Recovery per Claim | B24: =MAX(0, MIN(Inputs!B12-Inputs!B14, Inputs!B15)) -> 0 | C24: =B7*B24 -> 0
A25: Risk Reduction (₹) | C25: =C24 -> 0
A26: Risk Reduction (%) | C26: =IF(C22=0,0,C24/C22) -> 0
A27: =IF(Inputs!B12<=Inputs!B14,"⚠ NOTE: Avg severity (" & TEXT(Inputs!B12,"₹#,##0") & ") < Retention (" & TEXT(Inputs!B14,"₹#,##0") & ") — XL treaty provides no coverage at current severity.","✓ RI treaty triggered — reinsurer absorbs losses above retention.") -> ⚠ NOTE: Avg severity (₹1,20,000) < Retention (₹5,00,000) — XL treaty provides no coverage at current severity.
A28: D. STRESS TEST — 1-in-100 Year Scenario (1.5x Claims)
A29: Metric | B29: Base (₹) | C29: Stressed (₹)
A30: Total Claim Cost | B30: =B8 -> 60000000 | C30: =B8*1.5 -> 90000000
A31: Net Underwriting Profit | B31: =B11 -> 2000000 | C31: =B6-(C30+B9+B10) -> -28000000

Sheet Sensitivity Analysis
A1: SENSITIVITY ANALYSIS | One-Way Shocks to Key Assumptions
A2: Green = favorable outcome | Orange = adverse outcome | Blue = base case | Measure: Net Underwriting Profit (₹)
A4: 1. CLAIM FREQUENCY SENSITIVITY
B5: Metric | C5: -30% | D5: -10% | E5: Base (0%) | F5: +10% | G5: +30%
B6: Effective Claim Freq. | C6: =Inputs!$B$11*(1+-0.3) -> 0.007 | D6: =Inputs!$B$11*(1+-0.1) -> 0.009 | E6: =Inputs!$B$11*(1+0) -> 0.01 | F6: =Inputs!$B$11*(1+0.1) -> 0.011 | G6: =Inputs!$B$11*(1+0.3) -> 0.013
B7: Expected Gross Claims (₹) | C7: =Inputs!$B$10*Inputs!$B$11*(1+-0.3)*Inputs!$B$12 -> 42000000 | D7: =Inputs!$B$10*Inputs!$B$11*(1+-0.1)*Inputs!$B$12 -> 54000000 | E7: =Inputs!$B$10*Inputs!$B$11*(1+0)*Inputs!$B$12 -> 60000000 | F7: =Inputs!$B$10*Inputs!$B$11*(1+0.1)*Inputs!$B$12 -> 66000000 | G7: =Inputs!$B$10*Inputs!$B$11*(1+0.3)*Inputs!$B$12 -> 78000000
B8: Loss Ratio | C8: =(Inputs!$B$10*Inputs!$B$11*(1+-0.3)*Inputs!$B$12)/Inputs!$B$9 -> 0.42 | D8: =(Inputs!$B$10*Inputs!$B$11*(1+-0.1)*Inputs!$B$12)/Inputs!$B$9 -> 0.54 | E8: =(Inputs!$B$10*Inputs!$B$11*(1+0)*Inputs!$B$12)/Inputs!$B$9 -> 0.6 | F8: =(Inputs!$B$10*Inputs!$B$11*(1+0.1)*Inputs!$B$12)/Inputs!$B$9 -> 0.66 | G8: =(Inputs!$B$10*Inputs!$B$11*(1+0.3)*Inputs!$B$12)/Inputs!$B$9 -> 0.78
B9: Combined Ratio | C9: =(Inputs!$B$10*Inputs!$B$11*(1+-0.3)*Inputs!$B$12+Inputs!$B$9*Inputs!$B$13+Inputs!$B$9*Inputs!$B$16)/Inputs!$B$9 -> 0.8 | D9: =(Inputs!$B$10*Inputs!$B$11*(1+-0.1)*Inputs!$B$12+Inputs!$B$9*Inputs!$B$13+Inputs!$B$9*Inputs!$B$16)/Inputs!$B$9 -> 0.92 | E9: =(Inputs!$B$10*Inputs!$B$11*(1+0)*Inputs!$B$12+Inputs!$B$9*Inputs!$B$13+Inputs!$B$9*Inputs!$B$16)/Inputs!$B$9 -> 0.98 | F9: =(Inputs!$B$10*Inputs!$B$11*(1+0.1)*Inputs!$B$12+Inputs!$B$9*Inputs!$B$13+Inputs!$B$9*Inputs!$B$16)/Inputs!$B$9 -> 1.04 | G9: =(Inputs!$B$10*Inputs!$B$11*(1+0.3)*Inputs!$B$12+Inputs!$B$9*Inputs!$B$13+Inputs!$B$9*Inputs!$B$16)/Inputs!$B$9 -> 1.16
B10: Net Profit (₹) | C10: =Inputs!$B$9-(Inputs!$B$10*Inputs!$B$11*(1+-0.3)*Inputs!$B$12+Inputs!$B$9*Inputs!$B$13+Inputs!$B$9*Inputs!$B$16) -> 20000000 | D10: =Inputs!$B$9-(Inputs!$B$10*Inputs!$B$11*(1+-0.1)*Inputs!$B$12+Inputs!$B$9*Inputs!$B$13+Inputs!$B$9*Inputs!$B$16) -> 8000000 | E10: =Inputs!$B$9-(Inputs!$B$10*Inputs!$B$11*(1+0)*Inputs!$B$12+Inputs!$B$9*Inputs!$B$13+Inputs!$B$9*Inputs!$B$16) -> 2000000 | F10: =Inputs!$B$9-(Inputs!$B$10*Inputs!$B$11*(1+0.1)*Inputs!$B$12+Inputs!$B$9*Inputs!$B$13+Inputs!$B$9*Inputs!$B$16) -> -4000000 | G10: =Inputs!$B$9-(Inputs!$B$10*Inputs!$B$11*(1+0.3)*Inputs!$B$12+Inputs!$B$9*Inputs!$B$13+Inputs!$B$9*Inputs!$B$16) -> -16000000
A12: 2. CLAIM SEVERITY (INFLATION) SENSITIVITY
B13: Metric | C13: -20% | D13: -10% | E13: Base (0%) | F13: +10% | G13: +20%
B14: Avg Claim Severity (₹) | C14: =Inputs!$B$12*(1+-0.2) -> 96000 | D14: =Inputs!$B$12*(1+-0.1) -> 108000 | E14: =Inputs!$B$12*(1+0) -> 120000 | F14: =Inputs!$B$12*(1+0.1) -> 132000 | G14: =Inputs!$B$12*(1+0.2) -> 144000
B15: Expected Gross Claims (₹) | C15: =Inputs!$B$10*Inputs!$B$11*Inputs!$B$12*(1+-0.2) -> 48000000 | D15: =Inputs!$B$10*Inputs!$B$11*Inputs!$B$12*(1+-0.1) -> 54000000 | E15: =Inputs!$B$10*Inputs!$B$11*Inputs!$B$12*(1+0) -> 60000000 | F15: =Inputs!$B$10*Inputs!$B$11*Inputs!$B$12*(1+0.1) -> 66000000 | G15: =Inputs!$B$10*Inputs!$B$11*Inputs!$B$12*(1+0.2) -> 72000000
B16: Loss Ratio | C16: =(Inputs!$B$10*Inputs!$B$11*Inputs!$B$12*(1+-0.2))/Inputs!$B$9 -> 0.48 | D16: =(Inputs!$B$10*Inputs!$B$11*Inputs!$B$12*(1+-0.1))/Inputs!$B$9 -> 0.54 | E16: =(Inputs!$B$10*Inputs!$B$11*Inputs!$B$12*(1+0))/Inputs!$B$9 -> 0.6 | F16: =(Inputs!$B$10*Inputs!$B$11*Inputs!$B$12*(1+0.1))/Inputs!$B$9 -> 0.66 | G16: =(Inputs!$B$10*Inputs!$B$11*Inputs!$B$12*(1+0.2))/Inputs!$B$9 -> 0.72
B17: Combined Ratio | C17: =(Inputs!$B$10*Inputs!$B$11*Inputs!$B$12*(1+-0.2)+Inputs!$B$9*Inputs!$B$13+Inputs!$B$9*Inputs!$B$16)/Inputs!$B$9 -> 0.86 | D17: =(Inputs!$B$10*Inputs!$B$11*Inputs!$B$12*(1+-0.1)+Inputs!$B$9*Inputs!$B$13+Inputs!$B$9*Inputs!$B$16)/Inputs!$B$9 -> 0.92 | E17: =(Inputs!$B$10*Inputs!$B$11*Inputs!$B$12*(1+0)+Inputs!$B$9*Inputs!$B$13+Inputs!$B$9*Inputs!$B$16)/Inputs!$B$9 -> 0.98 | F17: =(Inputs!$B$10*Inputs!$B$11*Inputs!$B$12*(1+0.1)+Inputs!$B$9*Inputs!$B$13+Inputs!$B$9*Inputs!$B$16)/Inputs!$B$9 -> 1.04 | G17: =(Inputs!$B$10*Inputs!$B$11*Inputs!$B$12*(1+0.2)+Inputs!$B$9*Inputs!$B$13+Inputs!$B$9*Inputs!$B$16)/Inputs!$B$9 -> 1.1
B18: Net Profit (₹) | C18: =Inputs!$B$9-(Inputs!$B$10*Inputs!$B$11*Inputs!$B$12*(1+-0.2)+Inputs!$B$9*Inputs!$B$13+Inputs!$B$9*Inputs!$B$16) -> 14000000 | D18: =Inputs!$B$9-(Inputs!$B$10*Inputs!$B$11*Inputs!$B$12*(1+-0.1)+Inputs!$B$9*Inputs!$B$13+Inputs!$B$9*Inputs!$B$16) -> 8000000 | E18: =Inputs!$B$9-(Inputs!$B$10*Inputs!$B$11*Inputs!$B$12*(1+0)+Inputs!$B$9*Inputs!$B$13+Inputs!$B$9*Inputs!$B$16) -> 2000000 | F18: =Inputs!$B$9-(Inputs!$B$10*Inputs!$B$11*Inputs!$B$12*(1+0.1)+Inputs!$B$9*Inputs!$B$13+Inputs!$B$9*Inputs!$B$16) -> -4000000 | G18: =Inputs!$B$9-(Inputs!$B$10*Inputs!$B$11*Inputs!$B$12*(1+0.2)+Inputs!$B$9*Inputs!$B$13+Inputs!$B$9*Inputs!$B$16) -> -10000000
A20: 3. EXPENSE RATIO SENSITIVITY
B21: Metric | C21: 20% | D21: 25% | E21: 30% (Base) | F21: 35% | G21: 40%
B22: Operating Expenses (₹) | C22: =Inputs!$B$9*0.2 -> 20000000 | D22: =Inputs!$B$9*0.25 -> 25000000 | E22: =Inputs!$B$9*0.3 -> 30000000 | F22: =Inputs!$B$9*0.35 -> 35000000 | G22: =Inputs!$B$9*0.4 -> 40000000
B23: Combined Ratio | C23: =(Calculations!$B$8+Inputs!$B$9*0.2+Inputs!$B$9*Inputs!$B$16)/Inputs!$B$9 -> 0.88 | D23: =(Calculations!$B$8+Inputs!$B$9*0.25+Inputs!$B$9*Inputs!$B$16)/Inputs!$B$9 -> 0.93 | E23: =(Calculations!$B$8+Inputs!$B$9*0.3+Inputs!$B$9*Inputs!$B$16)/Inputs!$B$9 -> 0.98 | F23: =(Calculations!$B$8+Inputs!$B$9*0.35+Inputs!$B$9*Inputs!$B$16)/Inputs!$B$9 -> 1.03 | G23: =(Calculations!$B$8+Inputs!$B$9*0.4+Inputs!$B$9*Inputs!$B$16)/Inputs!$B$9 -> 1.08
B24: Net Profit (₹) | C24: =Inputs!$B$9-(Calculations!$B$8+Inputs!$B$9*0.2+Inputs!$B$9*Inputs!$B$16) -> 12000000 | D24: =Inputs!$B$9-(Calculations!$B$8+Inputs!$B$9*0.25+Inputs!$B$9*Inputs!$B$16) -> 7000000 | E24: =Inputs!$B$9-(Calculations!$B$8+Inputs!$B$9*0.3+Inputs!$B$9*Inputs!$B$16) -> 2000000 | F24: =Inputs!$B$9-(Calculations!$B$8+Inputs!$B$9*0.35+Inputs!$B$9*Inputs!$B$16) -> -3000000 | G24: =Inputs!$B$9-(Calculations!$B$8+Inputs!$B$9*0.4+Inputs!$B$9*Inputs!$B$16) -> -8000000
A26: 4. TORNADO SUMMARY | Risk Driver Ranking by Net Profit Swing
B27: Risk Driver | C27: Upside (Best) | D27: Base Case | E27: Downside (Worst) | F27: Swing (₹) | G27: Rank
B28: Claim Frequency ±30% | C28: =Inputs!B9-(Inputs!B10*Inputs!B11*0.7*Inputs!B12+Inputs!B9*Inputs!B13+Inputs!B9*Inputs!B16) -> 20000000 | D28: =Calculations!B11 -> 2000000 | E28: =Inputs!B9-(Inputs!B10*Inputs!B11*1.3*Inputs!B12+Inputs!B9*Inputs!B13+Inputs!B9*Inputs!B16) -> -16000000 | F28: =ABS(C28-E28) -> 36000000 | G28: 1
B29: Claim Severity ±20% | C29: =Inputs!B9-(Inputs!B10*Inputs!B11*Inputs!B12*0.8+Inputs!B9*Inputs!B13+Inputs!B9*Inputs!B16) -> 14000000 | D29: =Calculations!B11 -> 2000000 | E29: =Inputs!B9-(Inputs!B10*Inputs!B11*Inputs!B12*1.2+Inputs!B9*Inputs!B13+Inputs!B9*Inputs!B16) -> -10000000 | F29: =ABS(C29-E29) -> 24000000 | G29: 2
B30: Expense Ratio 20%→40% | C30: =Inputs!B9-(Calculations!B8+Inputs!B9*0.2+Inputs!B9*Inputs!B16) -> 12000000 | D30: =Calculations!B11 -> 2000000 | E30: =Inputs!B9-(Calculations!B8+Inputs!B9*0.4+Inputs!B9*Inputs!B16) -> -8000000 | F30: =ABS(C30-E30) -> 20000000 | G30: 3
B31: Reinsurance Cost 5%→11% | C31: =Inputs!B9-(Calculations!B8+Inputs!B9*Inputs!B13+Inputs!B9*0.05) -> 5000000 | D31: =Calculations!B11 -> 2000000 | E31: =Inputs!B9-(Calculations!B8+Inputs!B9*Inputs!B13+Inputs!B9*0.11) -> -1000000 | F31: =ABS(C31-E31) -> 6000000 | G31: 4
A32: Ranked by magnitude of swing — largest swing = greatest risk driver. Address top 2 drivers first.

Sheet Pricing Adequacy
A1: PRICING ADEQUACY | Required Premium Buildup & Adequacy Test
A2: Determines whether the current premium is sufficient to cover costs, risk margin, and capital charges
A4: A. PRICING ASSUMPTIONS
B5: Parameter | C5: Value | D5: Notes
B6: Target Combined Ratio | C6: 0.95 | D6: Profitability target — industry benchmark 90-95%
B7: Target Profit Margin | C7: 0.05 | D7: Minimum underwriting profit margin
B8: Risk Margin Loading | C8: 0.03 | D8: Uncertainty buffer added to pure claims cost
B9: Available Capital (₹) | C9: 20000000 | D9: Shareholder capital supporting this portfolio
B10: Required Return on Capital | C10: 0.1 | D10: Hurdle rate / WACC for capital allocation
A12: B. REQUIRED PREMIUM BUILDUP
B13: Cost Component | C13: Amount (₹) | D13: % of Required Prem
B14: Pure Loss Cost (Expected Claims) | C14: =Calculations!B8 -> 60000000 | D14: =C14/C19 -> 0.58939096
B15: Operating Expenses | C15: =Calculations!B9 -> 30000000 | D15: =C15/C19 -> 0.29469548
B16: Reinsurance Cost | C16: =Calculations!B10 -> 8000000 | D16: =C16/C19 -> 0.078585462
B17: Risk Margin (3% of claims) | C17: =Calculations!B8*0.03 -> 1800000 | D17: =C17/C19 -> 0.017681729
B18: Capital Cost (10% of capital) | C18: =C9*C10 -> 2000000 | D18: =C18/C19 -> 0.019646365
B19: REQUIRED PREMIUM (Total) | C19: =SUM(C14:C18) -> 101800000
A21: C. PRICING ADEQUACY CHECK
B22: Metric | C22: Value | D22: Target | E22: Status
B23: Current Gross Premium (₹) | C23: =Inputs!B9 -> 100000000 | D23: N/A | E23: —
B24: Required Premium (₹) | C24: =C19 -> 101800000 | D24: N/A | E24: —
B25: Pricing Surplus / (Deficit) | C25: =Inputs!B9-C19 -> -1800000 | D25: ≥ 0 | E25: —
B26: Premium Adequacy Ratio | C26: =Inputs!B9/C19 -> 0.98231827 | D26: ≥ 1.00x | E26: =IF(C26>=1,"✓ ADEQUATE","✗ UNDER-PRICED") -> ✗ UNDER-PRICED
B27: Actual Combined Ratio | C27: =Calculations!B18 -> 0.98 | D27: ≤ 95.0% | E27: =IF(C27<=0.95,"✓ ON TARGET",IF(C27<=1,"⚠ WATCH","✗ UNPROFITABLE")) -> ⚠ WATCH
B28: Implied Profit Margin | C28: =1-Calculations!B18 -> 0.02 | D28: ≥ 5.0% | E28: —

Sheet Capital & Solvency
A1: CAPITAL & SOLVENCY | Illustrative Solvency II-Style Capital View
A2: Required Capital = 99.5th Percentile VaR − Expected Loss | Solvency Ratio = Available Capital / Required Capital
A4: A. CAPITAL INPUT
B5: Parameter | C5: Value | D5: Notes
B6: Available Capital (₹) | C6: 20000000 | D6: Surplus equity allocated to portfolio
B7: Management Buffer % | C7: 0.2 | D7: Buffer above minimum SCR (management discretion)
A9: B. CAPITAL REQUIREMENT CALCULATIONS
B10: Capital Metric | C10: Amount (₹) | D10: Basis | E10: Interpretation
B11: Expected Loss (Best Estimate) | C11: =Calculations!B8 -> 60000000 | D11: Mean of loss distribution | E11: Best-estimate cost
B12: 95th Percentile VaR | C12: =Simulation!G8 -> 64560000 | D12: 1-in-20yr simulation | E12: Moderate tail event
B13: 99.5th Percentile VaR | C13: =Simulation!G9 -> 66960000 | D13: 1-in-200yr simulation (Solvency II) | E13: Solvency II SCR basis (1-in-200 year)
B14: Solvency Capital Req. (SCR) | C14: =Simulation!G9-Calculations!B8 -> 6960000 | D14: 99.5th VaR − Expected Loss | E14: Min capital to hold
B15: Management Buffer | C15: =C14*C7 -> 1392000 | D15: 20% × SCR | E15: Operational headroom
B16: Total Capital Requirement (TCR) | C16: =C14+C15 -> 8352000 | D16: SCR + Buffer | E16: Capital needed
A18: C. SOLVENCY RATIOS
B19: Ratio | C19: Value | D19: Threshold | E19: Status
B20: Solvency Ratio (Avail / TCR) | C20: =C6/C16 -> 2.394636 | D20: ≥ 1.00x | E20: =IF(C20>=1,"✓ SOLVENT","✗ CAPITAL SHORTFALL") -> ✓ SOLVENT
B21: SCR Coverage (Avail / SCR) | C21: =C6/C14 -> 2.8735632 | D21: ≥ 1.00x | E21: =IF(C21>=1,"✓ ADEQUATE","✗ BELOW SCR") -> ✓ ADEQUATE
B22: Capital Surplus / (Shortfall) | C22: =C6-C16 -> 11648000 | D22: ≥ 0 | E22: —
B23: Return on Req. Capital | C23: =Calculations!B11/C16 -> 0.2394636 | D23: ≥ 10.0% | E23: —

Sheet Simulation
A1: MONTE CARLO SIMULATION | 5,000 Iterations — Poisson Frequency Model
A2: Simulation uses Normal approximation to Poisson for large λ (λ=500), which is appropriate due to Central Limit Theorem and improves computational efficiency.
A4: Sim # | B4: U ~ Uniform(0,1) | C4: Claim Count [Poisson(λ)] | D4: Simulated Claim Cost (₹) | F4: Risk Metric (incl. SCR) | G4: Value
A5: 1 | B5: =RAND() -> 0.72837932 | C5: {=MAX(0,ROUND(Inputs!$B$10*Inputs!$B$11+NORMSINV(B5)*SQRT(Inputs!$B$10*Inputs!$B$11),0))} -> 514 | D5: =C5*Inputs!$B$12 -> 61680000 | F5: Average Simulated Loss (₹) | G5: =AVERAGE(D5:D5004) -> 60044256
A6: 2 | B6: =RAND() -> 0.26851246 | C6: {=MAX(0,ROUND(Inputs!$B$10*Inputs!$B$11+NORMSINV(B6)*SQRT(Inputs!$B$10*Inputs!$B$11),0))} -> 486 | D6: =C6*Inputs!$B$12 -> 58320000 | F6: Median Simulated Loss (₹) | G6: =MEDIAN(D5:D5004) -> 60000000
A7: 3 | B7: =RAND() -> 0.93937329 | C7: {=MAX(0,ROUND(Inputs!$B$10*Inputs!$B$11+NORMSINV(B7)*SQRT(Inputs!$B$10*Inputs!$B$11),0))} -> 535 | D7: =C7*Inputs!$B$12 -> 64200000 | F7: Worst-Case Loss (₹) | G7: =MAX(D5:D5004) -> 69000000
A8: 4 | B8: =RAND() -> 0.29702805 | C8: {=MAX(0,ROUND(Inputs!$B$10*Inputs!$B$11+NORMSINV(B8)*SQRT(Inputs!$B$10*Inputs!$B$11),0))} -> 488 | D8: =C8*Inputs!$B$12 -> 58560000 | F8: 95th Percentile VaR (₹) | G8: =PERCENTILE(D5:D5004,0.95) -> 64560000
A9: 5 | B9: =RAND() -> 0.075477893 | C9: {=MAX(0,ROUND(Inputs!$B$10*Inputs!$B$11+NORMSINV(B9)*SQRT(Inputs!$B$10*Inputs!$B$11),0))} -> 468 | D9: =C9*Inputs!$B$12 -> 56160000 | F9: 99.5th Percentile VaR (₹) | G9: =PERCENTILE(D5:D5004,0.995) -> 66960000
A10: 6 | B10: =RAND() -> 0.82316439 | C10: {=MAX(0,ROUND(Inputs!$B$10*Inputs!$B$11+NORMSINV(B10)*SQRT(Inputs!$B$10*Inputs!$B$11),0))} -> 521 | D10: =C10*Inputs!$B$12 -> 62520000 | F10: Prob. Aggregate Loss > Gross Premium | G10: =COUNTIF(D5:D5004,">"&Inputs!B9)/5000 -> 0
A11: 7 | B11: =RAND() -> 0.32946667 | C11: {=MAX(0,ROUND(Inputs!$B$10*Inputs!$B$11+NORMSINV(B11)*SQRT(Inputs!$B$10*Inputs!$B$11),0))} -> 490 | D11: =C11*Inputs!$B$12 -> 58800000 | F11: Probability of Technical Ruin | G11: =COUNTIF(D5:D5004,">"&(Inputs!B9+Inputs!B9*0.2))/5000 -> 0
A12: 8 | B12: =RAND() -> 0.5802067 | C12: {=MAX(0,ROUND(Inputs!$B$10*Inputs!$B$11+NORMSINV(B12)*SQRT(Inputs!$B$10*Inputs!$B$11),0))} -> 505 | D12: =C12*Inputs!$B$12 -> 60600000 | F12: Simulated Loss Std Dev (₹) | G12: =STDEV(D5:D5004) -> 2671693.6
A13: 9 | B13: =RAND() -> 0.83786909 | C13: {=MAX(0,ROUND(Inputs!$B$10*Inputs!$B$11+NORMSINV(B13)*SQRT(Inputs!$B$10*Inputs!$B$11),0))} -> 522 | D13: =C13*Inputs!$B$12 -> 62640000
A14: 10 | B14: =RAND() -> 0.54742589 | C14: {=MAX(0,ROUND(Inputs!$B$10*Inputs!$B$11+NORMSINV(B14)*SQRT(Inputs!$B$10*Inputs!$B$11),0))} -> 503 | D14: =C14*Inputs!$B$12 -> 60360000 | F14: Method: Poisson Normal Approx — valid since λ=500 >> 30 (CLT applies)
A15: 11 | B15: =RAND() -> 0.62952594 | C15: {=MAX(0,ROUND(Inputs!$B$10*Inputs!$B$11+NORMSINV(B15)*SQRT(Inputs!$B$10*Inputs!$B$11),0))} -> 507 | D15: =C15*Inputs!$B$12 -> 60840000 | F15: λ = 50,000 policies × 1.0% freq = 500. σ = √500 ≈ 22.4 claims.
A16: 12 | B16: =RAND() -> 0.33253851 | C16: {=MAX(0,ROUND(Inputs!$B$10*Inputs!$B$11+NORMSINV(B16)*SQRT(Inputs!$B$10*Inputs!$B$11),0))} -> 490 | D16: =C16*Inputs!$B$12 -> 58800000
A17: 13 | B17: =RAND() -> 0.61857765 | C17: {=MAX(0,ROUND(Inputs!$B$10*Inputs!$B$11+NORMSINV(B17)*SQRT(Inputs!$B$10*Inputs!$B$11),0))} -> 507 | D17: =C17*Inputs!$B$12 -> 60840000
A18: 14 | B18: =RAND() -> 0.92222225 | C18: {=MAX(0,ROUND(Inputs!$B$10*Inputs!$B$11+NORMSINV(B18)*SQRT(Inputs!$B$10*Inputs!$B$11),0))} -> 532 | D18: =C18*Inputs!$B$12 -> 63840000
A19: 15 | B19: =RAND() -> 0.99217827 | C19: {=MAX(0,ROUND(Inputs!$B$10*Inputs!$B$11+NORMSINV(B19)*SQRT(Inputs!$B$10*Inputs!$B$11),0))} -> 554 | D19: =C19*Inputs!$B$12 -> 66480000
A20: 16 | B20: =RAND() -> 0.20474202 | C20: {=MAX(0,ROUND(Inputs!$B$10*Inputs!$B$11+NORMSINV(B20)*SQRT(Inputs!$B$10*Inputs!$B$11),0))} -> 482 | D20: =C20*Inputs!$B$12 -> 57840000
A21: 17 | B21: =RAND() -> 0.80119187 | C21: {=MAX(0,ROUND(Inputs!$B$10*Inputs!$B$11+NORMSINV(B21)*SQRT(Inputs!$B$10*Inputs!$B$11),0))} -> 519 | D21: =C21*Inputs!$B$12 -> 62280000
A22: 18 | B22: =RAND() -> 0.34962979 | C22: {=MAX(0,ROUND(Inputs!$B$10*Inputs!$B$11+NORMSINV(B22)*SQRT(Inputs!$B$10*Inputs!$B$11),0))} -> 491 | D22: =C22*Inputs!$B$12 -> 58920000
A23: 19 | B23: =RAND() -> 0.24232639 | C23: {=MAX(0,ROUND(Inputs!$B$10*Inputs!$B$11+NORMSINV(B23)*SQRT(Inputs!$B$10*Inputs!$B$11),0))} -> 484 | D23: =C23*Inputs!$B$12 -> 58080000
A24: 20 | B24: =RAND() -> 0.50026334 | C24: {=MAX(0,ROUND(Inputs!$B$10*Inputs!$B$11+NORMSINV(B24)*SQRT(Inputs!$B$10*Inputs!$B$11),0))} -> 500 | D24: =C24*Inputs!$B$12 -> 60000000
A25: 21 | B25: =RAND() -> 0.59316445 | C25: {=MAX(0,ROUND(Inputs!$B$10*Inputs!$B$11+NORMSINV(B25)*SQRT(Inputs!$B$10*Inputs!$B$11),0))} -> 505 | D25: =C25*Inputs!$B$12 -> 60600000
A26: 22 | B26: =RAND() -> 0.12234215 | C26: {=MAX(0,ROUND(Inputs!$B$10*Inputs!$B$11+NORMSINV(B26)*SQRT(Inputs!$B$10*Inputs!$B$11),0))} -> 474 | D26: =C26*Inputs!$B$12 -> 56880000
A27: 23 | B27: =RAND() -> 0.96050216 | C27: {=MAX(0,ROUND(Inputs!$B$10*Inputs!$B$11+NORMSINV(B27)*SQRT(Inputs!$B$10*Inputs!$B$11),0))} -> 539 | D27: =C27*Inputs!$B$12 -> 64680000
... A5004: 5000 | B5004: =RAND() -> 0.8819926 | C5004: {=MAX(0,ROUND(Inputs!$B$10*Inputs!$B$11+NORMSINV(B5004)*SQRT(Inputs!$B$10*Inputs!$B$11),0))} -> 526 | D5004: =C5004*Inputs!$B$12 -> 63120000

Sheet Scenario Comparison
A1: SCENARIO COMPARISON | Base vs Optimistic vs Stress — Full Side-by-Side
A2: All three scenarios calculated simultaneously — independent of the active scenario selector in Inputs
A4: FULL PORTFOLIO METRICS BY SCENARIO
B5: Metric | C5: Base Case | D5: Optimistic | E5: Stress | F5: Stress vs Base
B6: Gross Premium | C6: =Inputs!D9 -> 100000000 | D6: =Inputs!E9 -> 120000000 | E6: =Inputs!F9 -> 80000000 | F6: =E6-C6 -> -20000000
B7: Policy Count | C7: =Inputs!D10 -> 50000 | D7: =Inputs!E10 -> 60000 | E7: =Inputs!F10 -> 40000 | F7: =E7-C7 -> -10000
B8: Claim Frequency | C8: =Inputs!D11 -> 0.01 | D8: =Inputs!E11 -> 0.005 | E8: =Inputs!F11 -> 0.02 | F8: =E8-C8 -> 0.01
B9: Avg Severity (₹) | C9: =Inputs!D12 -> 120000 | D9: =Inputs!E12 -> 100000 | E9: =Inputs!F12 -> 150000 | F9: =E9-C9 -> 30000
B10: Expected Claims | C10: =Inputs!D10*Inputs!D11 -> 500 | D10: =Inputs!E10*Inputs!E11 -> 300 | E10: =Inputs!F10*Inputs!F11 -> 800 | F10: =E10-C10 -> 300
B11: Gross Claims (₹) | C11: =(Inputs!D10*Inputs!D11*Inputs!D12) -> 60000000 | D11: =(Inputs!E10*Inputs!E11*Inputs!E12) -> 30000000 | E11: =(Inputs!F10*Inputs!F11*Inputs!F12) -> 120000000 | F11: =E11-C11 -> 60000000
B12: Expenses (₹) | C12: =(Inputs!D9*Inputs!D13) -> 30000000 | D12: =(Inputs!E9*Inputs!E13) -> 33600000 | E12: =(Inputs!F9*Inputs!F13) -> 26400000 | F12: =E12-C12 -> -3600000
B13: RI Cost (₹) | C13: =(Inputs!D9*Inputs!D16) -> 8000000 | D13: =(Inputs!E9*Inputs!E16) -> 8400000 | E13: =(Inputs!F9*Inputs!F16) -> 8000000 | F13: =E13-C13 -> 0
B14: Net Profit (₹) | C14: =(Inputs!D9-(Inputs!D10*Inputs!D11*Inputs!D12)-(Inputs!D9*Inputs!D13)-(Inputs!D9*Inputs!D16)) -> 2000000 | D14: =(Inputs!E9-(Inputs!E10*Inputs!E11*Inputs!E12)-(Inputs!E9*Inputs!E13)-(Inputs!E9*Inputs!E16)) -> 48000000 | E14: =(Inputs!F9-(Inputs!F10*Inputs!F11*Inputs!F12)-(Inputs!F9*Inputs!F13)-(Inputs!F9*Inputs!F16)) -> -74400000 | F14: =E14-C14 -> -76400000
B15: Loss Ratio | C15: =(Inputs!D10*Inputs!D11*Inputs!D12)/Inputs!D9 -> 0.6 | D15: =(Inputs!E10*Inputs!E11*Inputs!E12)/Inputs!E9 -> 0.25 | E15: =(Inputs!F10*Inputs!F11*Inputs!F12)/Inputs!F9 -> 1.5 | F15: =E15-C15 -> 0.9
B16: Expense Ratio | C16: =Inputs!D13 -> 0.3 | D16: =Inputs!E13 -> 0.28 | E16: =Inputs!F13 -> 0.33 | F16: =E16-C16 -> 0.03
B17: Combined Ratio | C17: =((Inputs!D10*Inputs!D11*Inputs!D12)+(Inputs!D9*Inputs!D13)+(Inputs!D9*Inputs!D16))/Inputs!D9 -> 0.98 | D17: =((Inputs!E10*Inputs!E11*Inputs!E12)+(Inputs!E9*Inputs!E13)+(Inputs!E9*Inputs!E16))/Inputs!E9 -> 0.6 | E17: =((Inputs!F10*Inputs!F11*Inputs!F12)+(Inputs!F9*Inputs!F13)+(Inputs!F9*Inputs!F16))/Inputs!F9 -> 1.93 | F17: =E17-C17 -> 0.95
A19: Blue=Base | Green=Optimistic | Orange=Stress | Stress vs Base = deterioration in worst-case scenario

Sheet Dashboard
A1: INSURANCE RISK MODEL | Executive Dashboard
A2: Auto-calculated from Inputs sheet | Change scenario in Inputs!B5
A4: KEY PERFORMANCE INDICATORS
B5: Net Underwriting Profit (₹) | E5: 95th Pctile VaR (₹)
B6: =Calculations!B11 -> 2000000 | E6: =Simulation!G8 -> 64560000
B8: Loss Ratio | E8: 99.5th Pctile VaR (₹)
B9: =Calculations!B15 -> 0.6 | E9: =Simulation!G9 -> 66960000
B11: Combined Ratio | E11: Prob. of Loss > Premium
B12: =Calculations!B18 -> 0.98 | E12: =Simulation!G10 -> 0
B14: Reinsurance Cost (₹) | E14: Risk Reduction (RI)
B15: =Calculations!B10 -> 8000000 | E15: =Calculations!C25 -> 0
B17: Pricing Adequacy Status | C17: =IF('Pricing Adequacy'!C26>=1,"✓ ADEQUATE","✗ UNDER-PRICED — Rate increase required") -> ✗ UNDER-PRICED — Rate increase required
A18: RISK STATUS ASSESSMENT
B19: Portfolio Profitability Status | C19: =IF(Calculations!B11>0,"✓ PROFITABLE","✗ LOSS-MAKING") -> ✓ PROFITABLE
B20: Combined Ratio Status | C20: =IF(Calculations!B18<=0.95,"✓ ON TARGET",IF(Calculations!B18<1,"⚠ WATCH","✗ UNPROFITABLE")) -> ⚠ WATCH
B21: Scenario | C21: =Inputs!B5 -> Base

Sheet Model Notes
A1: MODEL DOCUMENTATION | Purpose, Methodology & Technical Reference
A2: Read this sheet before presenting the model | Updated March 2026
A4: 1. MODEL PURPOSE & OBJECTIVE
B5: Formal Objective | C5: To evaluate the profitability, risk exposure, and capital adequacy of a non-life insurance portfolio using both deterministic and stochastic actuarial modelling techniques. The model provides a complete view of portfolio economics from gross premium to net profit, including the cost and benefit of reinsurance, under multiple operating scenarios.
B6: Five Business Questions This Model Answers | C6: 1. Is the portfolio profitable? → Underwriting P&L, Loss Ratio, Combined Ratio 2. How risky is it under normal conditions? → Sensitivity Analysis, VaR 3. What happens in stress scenarios? → Scenario Comparison, Stress Test 4. How likely is extreme loss? → Monte Carlo Simulation, Probability of Ruin 5. Is the company holding enough capital? → Capital & Solvency (Solvency II framework)
B7: Intended Users | C7: Primary: Actuaries, Risk Managers, Chief Risk Officer (CRO) Secondary: Chief Financial Officer (CFO), Reinsurance counterparties, Board Risk Committee Suitable for: Interview presentation, portfolio review, pricing sign-off documentation
B8: Model Classification | C8: Actuarial Internal Model — Non-Life Insurance | Asset class: Property & Casualty / General Insurance Regulatory alignment: Solvency II Pillar 1 (SCR calculation approach) Version: 3.0 | Last updated: March 2026 | Author: [Your Name]
A10: 2. SHEET GUIDE (Navigate in this order)
B11: 1. Management Summary | C11: START HERE. One-page executive view. Eight KPI cards, automated risk status assessment (Profitable / Solvent / Adequately Priced), and a written recommendation. Designed to be printed for board meetings.
B12: 2. Inputs | C12: All user-adjustable assumptions — blue cells only. Toggle the Active Scenario (cell B5) between Base / Optimistic / Stress to update the entire model. Never edit black or green cells.
B13: 3. Calculations | C13: Deterministic P&L waterfall (Gross Premium → Net Profit), key underwriting ratios (Loss Ratio, Expense Ratio, Combined Ratio), reinsurance recovery analysis, and 1-in-100 year stress test.
B14: 4. Sensitivity Analysis | C14: One-way sensitivity tables for three key drivers: Claim Frequency (±30%), Claim Severity / Inflation (±20%), and Expense Ratio (20%–40%). Includes a Tornado table ranking drivers by profit swing magnitude.
B15: 5. Pricing Adequacy | C15: Bottom-up required premium buildup. Tests whether current premium covers: pure losses + expenses + reinsurance cost + risk margin + capital charge. Computes Premium Adequacy Ratio and pricing status.
B16: 6. Capital & Solvency | C16: Solvency II–aligned capital framework. Calculates Solvency Capital Requirement (SCR = 99.5th VaR − Expected Loss), Management Buffer, Total Capital Requirement, and Solvency Ratio.
B17: 7. Simulation | C17: 5,000-iteration Monte Carlo model. Claim counts drawn from Poisson(λ) distribution via the Normal approximation method. Produces full loss distribution with VaR at 95th / 99.5th percentile. Press F9 to recalculate.
B18: 8. Scenario Comparison | C18: All three scenarios (Base, Optimistic, Stress) computed simultaneously side-by-side. Stress vs Base delta column shows deterioration magnitude. Independent of the scenario selector.
B19: 9. Dashboard | C19: Visual KPI summary. Pull-forward of key metrics from Calculations and Simulation sheets.
B20: 10. Model Notes (this sheet) | C20: Full technical documentation. Should be read before presenting the model to a technical audience.
A22: 3. METHODOLOGY (Technical Detail)
B23: Expected Claims | C23: Expected Claim Count = Number of Policies × Claim Frequency Base case: 50,000 policies × 1.0% frequency = 500 expected claims Expected Gross Loss Cost = Expected Claims × Average Claim Severity
B24: Monte Carlo — Poisson Frequency Model | C24: Claim count in each trial is drawn from a Poisson(λ) distribution where λ = expected claim count. Implementation (Excel Normal Approximation): N = MAX(0, ROUND(λ + NORM.S.INV(U) × √λ, 0)) where U ~ Uniform(0,1) from RAND(). Why Poisson is correct: (1) Claim counts are non-negative integers. (2) The Poisson distribution is the standard actuarial model for claim frequency. (3) Variance equals the mean (key Poisson property), meaning higher expected frequency → proportionally more uncertainty. (4) Distribution is right-skewed — capturing the real-world asymmetry where bad outcomes are more likely than equally good ones. Why Normal approximation is valid here: λ = 500 >> 30. By the Central Limit Theorem, Poisson(500) is extremely well-approximated by Normal(500, √500). Maximum error in tail probabilities < 0.1%.
B25: Previous Model vs Current Approach | C25: Previous (v1-v2): N = Policies × Frequency × (1 + (RAND()-0.5) × 0.6) Problems: (1) Could produce fractional claim counts. (2) Symmetric — understates right tail. (3) Fixed ±30% band regardless of portfolio size. (4) No statistical distributional basis. Current (v3): N = MAX(0, ROUND(λ + NORM.S.INV(RAND()) × √λ, 0)) Improvements: (1) Integer claim counts. (2) Correct Poisson variance scaling. (3) Proper right skew. (4) Actuarially defensible — this is what actuaries use in practice.
B26: Reinsurance Structure | C26: Per-occurrence Excess-of-Loss (XL) treaty with a single retention limit. Insurer pays: min(Claim Severity, Retention Limit) Reinsurer pays: max(0, Claim Severity − Retention Limit) Current structure: ₹500,000 retention per claim. Any individual claim above this is ceded to the RI. ⚠ Note: At current average severity of ₹120,000, all claims fall below the retention limit — the XL treaty provides no coverage under base case assumptions. The treaty would activate if individual claim severity exceeds ₹500,000 (e.g. large loss or CAT event).
B27: Capital Requirement (Solvency II Approach) | C27: Solvency Capital Requirement (SCR) = 99.5th Percentile VaR − Expected Loss Interpretation: Capital needed to absorb losses beyond best estimate in a 1-in-200 year event. Management Buffer = 20% × SCR (management discretion, above regulatory minimum) Total Capital Requirement (TCR) = SCR + Management Buffer Solvency Ratio = Available Capital / TCR (must exceed 1.0x to be solvent)
B28: Stress Test | C28: 1.5× expected claims — approximating a 1-in-100 year frequency event per Lloyd's / industry convention. Stressed Claims = Base Expected Claims × 1.5 = ₹60,000,000 × 1.5 = ₹90,000,000 Stressed Net Profit = Gross Premium − (Stressed Claims + Expenses + RI Cost) = ₹100,000,000 − (₹90,000,000 + ₹30,000,000 + ₹8,000,000) = −₹28,000,000 Applied to claim cost only; severity per claim is held constant (severity stress is captured in Sensitivity Analysis).
B29: Pricing Adequacy Required Premium | C29: Required Premium = Expected Claims + Expenses + RI Cost + Risk Margin + Capital Cost Risk Margin = 3% of expected claims (loading for model uncertainty) Capital Cost = Available Capital × Required Return on Capital (10% hurdle rate) = ₹20,000,000 × 10% = ₹2,000,000 Required Premium (Base Case) = ₹60,000,000 + ₹30,000,000 + ₹8,000,000 + ₹1,800,000 + ₹2,000,000 = ₹101,800,000 Premium Adequacy Ratio = Actual Premium / Required Premium (target ≥ 1.0x) Base Case Result: ₹100,000,000 / ₹101,800,000 = 0.982x → ✗ UNDER-PRICED Implication: Current premium does not fully recover the capital charge. A rate increase of approximately 1.8% is required to achieve pricing adequacy.
A31: 4. COLOR CODING & NAVIGATION GUIDE
B32: Blue text | C32: Hard-coded input value — user may change freely
B33: Black text | C33: Formula or calculated result — do not edit
B34: Green text | C34: Cross-sheet reference pulling from another worksheet
B35: Dark navy header | C35: Section title / title row — structural formatting
B36: Mid-blue header | C36: Column header row
B37: Light blue fill | C37: Key result or summary output
B38: Green fill | C38: Favourable outcome / passing status check
B39: Orange fill | C39: Adverse or stressed outcome
B40: Yellow fill | C40: Methodology note or annotation
A42: 5. LIMITATIONS & FUTURE ENHANCEMENTS
B43: Claim Severity | C43: Current: Constant average severity per claim. Future: Replace with LogNormal(μ, σ) distribution to model the heavy right tail of large claims. This would materially increase 99.5th VaR estimates.
B44: Frequency–Severity Correlation | C44: Current: Frequency and severity are independent. Future: Introduce a positive correlation parameter — in catastrophe events both frequency and severity tend to rise simultaneously.
B45: Claims Inflation | C45: Current: No inflation loading. Future: Add an annual severity escalation factor (e.g. CPI + 2%) compounded over a 3–5 year projection period.
...
